Workbook

Sheet 2025
A1: Date Start | B1: Date End | C1: Monday | D1: Tuesday | E1: Wednesday | F1: Thursday | G1: Friday | H1: Saturday | I1: Sunday | J1: Total | K1: % change | L1: Notes | M1: Monthly Sales Tax | N1: Net Sales | O1: Tax Payment | P1: 0.08 | Q1: Projected | R1: Difference | S1: Rolling Difference
A2: 46021 | B2: 45662 | C2: 7526.6 | D2: 0 | E2: 3689.55 | F2: 6453.51 | G2: 11241.1 | H2: 14053.74 | I2: 5195.91 | J2: 48160.4 | L2: Closed for NYE, Jan 1 slow | M2: January | N2: 178480 | O2: =N2*$P$1 -> 14278.4 | Q2: 187244 | R2: =N2-Q2 -> -8764 | S2: =N2-Q2 -> -8764 | T2: =N2-Q2 -> -8764
A3: =A2+7 -> 46028 | B3: =B2+7 -> 45669 | C3: 3232.85 | D3: 0 | E3: 4285 | F3: 4601.65 | G3: 9380.6 | H3: 14013.45 | I3: 3276.11 | J3: 38789.66 | K3: =(J3-J2)/J2 -> -0.19457355 | M3: February | N3: 165973.39 | O3: =N3*$P$1 -> 13277.871 | Q3: 187244 | R3: =N3-Q3 -> -21270.61 | S3: =R3+S2 -> -30034.61 | T3: =R3+S2 -> -30034.61
A4: =A3+7 -> 46035 | B4: =B3+7 -> 45676 | C4: 2873.63 | D4: 0 | E4: 3636.3 | F4: 4807.4 | G4: 10376.25 | H4: 10088.6 | I4: 6109.2 | J4: 37891.38 | K4: =(J4-J3)/J3 -> -0.023157718 | M4: March | N4: 183697.3 | O4: =N4*$P$1 -> 14695.784 | Q4: 187244 | R4: =N4-Q4 -> -3546.7 | S4: =R4+S3 -> -33581.31 | T4: =R4+S3 -> -33581.31 | U4: =SUM(N2:N4) -> 528150.69
A5: 45677 | B5: 45683 | C5: 1724 | D5: 0 | E5: 2215.5 | F5: 4748.75 | G5: 12688.2 | H5: 14742.33 | I5: 3842.2 | J5: 39960.98 | K5: =(J5-J4)/J4 -> 0.054619283 | M5: April | N5: 152004.96 | O5: =N5*$P$1 -> 12160.397 | P5: 12166.82 | Q5: 187244 | R5: =N5-Q5 -> -35239.04 | S5: =R5+S4 -> -68820.35 | T5: =R5+S4 -> -68820.35
A6: 45684 | B6: 45690 | C6: 3493.05 | D6: 0 | E6: 4034.15 | F6: 3766.75 | G6: 10237.15 | H6: 15657.91 | I6: 5008.25 | J6: 42197.26 | K6: =(J6-J5)/J5 -> 0.055961591 | L6: Dry January over, Fire and ice Chili cookoff social Downtown Sat Feb 1 | M6: May | N6: 217601.23 | O6: =N6*$P$1 -> 17408.098 | P6: 17430.21 | Q6: 187244 | R6: =N6-Q6 -> 30357.23 | S6: =R6+S5 -> -38463.12 | T6: =R6+S5 -> -38463.12
A7: 45691 | B7: 45697 | C7: 2809.11 | D7: 4391 | E7: 3380.3 | F7: 4906 | G7: 8830.45 | H7: 12087.75 | I7: 1122 | J7: 37526.61 | K7: =(J7-J6)/J6 -> -0.1106861 | M7: June | N7: 229785.25 | O7: =N7*$P$1 -> 18382.82 | P7: 18385.83 | Q7: 201393 | R7: =N7-Q7 -> 28392.25 | S7: =R7+S6 -> -10070.87 | T7: =R7+S6 -> -10070.87 | U7: =SUM(N5:N7) -> 599391.44
A8: =A7+7 -> 45698 | B8: =B7+7 -> 45704 | C8: 1424 | D8: 0 | E8: 1854 | F8: 6612 | G8: 16427 | H8: 15530 | I8: 7548 | J8: =SUM(C8:I8) -> 49395 | K8: =(J8-J7)/J7 -> 0.31626598 | L8: Hide main hours to book pre/post center | M8: July | N8: 250092.41 | O8: =N8*$P$1 -> 20007.393 | P8: 20019.3 | Q8: 201393 | R8: =N8-Q8 -> 48699.41 | S8: =R8+S7 -> 38628.54 | T8: =R8+S7 -> 38628.54
A9: =A8+7 -> 45705 | B9: =B8+7 -> 45711 | C9: 1873 | D9: 0 | E9: 3576 | F9: 3388 | G9: 10389 | H9: 13440 | I9: 4428 | J9: =SUM(C9:I9) -> 37094 | K9: =(J9-J8)/J8 -> -0.2490333 | L9: Chocolate walk sunday was ok | M9: August | N9: 275180.48 | O9: =N9*$P$1 -> 22014.438 | P9: 21999.47 | Q9: 201393 | R9: =N9-Q9 -> 73787.48 | S9: =N9-Q9+S8 -> 112416.02 | T9: =R9+S8 -> 112416.02
A10: =A9+7 -> 45712 | B10: =B9+7 -> 45718 | C10: 2144 | D10: 0 | E10: 2466 | F10: 5886 | G10: 10886 | H10: 13701 | I10: 5490 | J10: =SUM(C10:I10) -> 40573 | K10: =(J10-J9)/J9 -> 0.093788753 | M10: September | N10: 206496.41 | O10: =N10*$P$1 -> 16519.713 | P10: 16536.73 | Q10: 201393 | R10: =N10-Q10 -> 5103.41 | S10: =N10-Q10+S9 -> 117519.43 | T10: =R10+S9 -> 117519.43 | U10: =SUM(N8:N10) -> 731769.3
A11: =A10+7 -> 45719 | B11: =B10+7 -> 45725 | C11: 1961 | D11: 0 | E11: 3458 | F11: 2996.6 | G11: 10998 | H11: 12545 | I11: 5549 | J11: =SUM(C11:I11) -> 37507.6 | K11: =(J11-J10)/J10 -> -0.075552707 | M11: October | N11: 196724.55 | O11: =N11*$P$1 -> 15737.964 | P11: 15747.47 | Q11: 201393 | R11: =N11-Q11 -> -4668.45 | S11: =N11-Q11+S10 -> 112850.98 | T11: =R11+S10 -> 112850.98
A12: =A11+7 -> 45726 | B12: =B11+7 -> 45732 | C12: 4895 | D12: 0 | E12: 4403 | F12: 2945 | G12: 10542 | H12: 11247 | I12: 3112 | J12: =SUM(C12:I12) -> 37144 | K12: =(J12-J11)/J11 -> -0.0096940353 | M12: November | N12: 180261.16 | O12: =N12*$P$1 -> 14420.893 | P12: 14431.86 | Q12: 187244 | R12: =N12-Q12 -> -6982.84 | S12: =N12-Q12+S11 -> 105868.14 | T12: =R12+S11 -> 105868.14
A13: =A12+7 -> 45733 | B13: =B12+7 -> 45739 | C13: 3681 | D13: 0 | E13: 4574 | F13: 4023 | G13: 11199 | H13: 14365 | I13: 5519 | J13: =SUM(C13:I13) -> 43361 | K13: =(J13-J12)/J12 -> 0.16737562 | M13: December | O13: =N13*$P$1 -> 0 | Q13: 187244 | R13: =N13-Q13 -> -187244 | S13: =N13-Q13+S12 -> -81375.86 | T13: =R13+S12 -> -81375.86
A14: =A13+7 -> 45740 | B14: =B13+7 -> 45746 | C14: 2821 | D14: 0 | E14: 4872 | F14: 3809 | G14: 11848 | H14: 12858 | I14: 7089 | J14: =SUM(C14:I14) -> 43297 | K14: =(J14-J13)/J13 -> -0.0014759807 | M14: Total | N14: =SUM(N2:N13) -> 2236297.1 | O14: =SUM(O2:O13) -> 178903.77 | Q14: =SUM(Q2:Q13) -> 2317673
A15: 45747 | B15: 45753 | C15: 3355 | D15: 0 | E15: 3614 | F15: 4382 | G15: 10897 | H15: 11210 | I15: 6114.5 | J15: =SUM(C15:I15) -> 39572.5 | K15: =(J15-J14)/J14 -> -0.086022126
A16: 45754 | B16: 45760 | C16: 2556 | D16: 0 | E16: 2715 | F16: 5123 | G16: 9878 | H16: 12989 | I16: 4164 | J16: =SUM(C16:I16) -> 37425 | K16: =(J16-J15)/J15 -> -0.054267484
A17: 45761 | B17: 45767 | C17: 3225 | D17: 0 | E17: 3603 | F17: 4944 | G17: 11764 | H17: 11381 | I17: 2925 | J17: =SUM(C17:I17) -> 37842 | K17: =(J17-J16)/J16 -> 0.011142285 | L17: Easter Sunday dead
A18: 45768 | B18: 45774 | C18: 2902 | D18: 0 | E18: 3032 | F18: 4640 | G18: 10664 | H18: 11291 | I18: 2941 | J18: =SUM(C18:I18) -> 35470 | K18: =(J18-J17)/J17 -> -0.062681676
A19: 45775 | B19: 45781 | C19: 2822 | D19: 0 | E19: 2386 | F19: 6288 | G19: 11945 | H19: 12110 | I19: 4341 | J19: =SUM(C19:I19) -> 39892 | K19: =(J19-J18)/J18 -> 0.12466873 | L19: Opened patio
A20: 45782 | B20: 45788 | C20: 1474 | D20: 0 | E20: 4041 | F20: 3588 | G20: 11708 | H20: 14558 | I20: 15587.75 | J20: =SUM(C20:I20) -> 50956.75 | K20: =(J20-J19)/J19 -> 0.27736764 | L20: Mother's day, graduation week, nice weather
A21: 45789 | B21: 45795 | C21: 3653 | D21: 0 | E21: 4927 | F21: 5650 | G21: 11726 | H21: 13835 | I21: 8377 | J21: =SUM(C21:I21) -> 48168 | K21: =(J21-J20)/J20 -> -0.054727784 | L21: Good weather/ wind Thurs/Fri, Graduation Sat
A22: 45796 | B22: 45802 | C22: 3299 | D22: 0 | E22: 5200 | F22: 4369 | G22: 14274 | H22: 10887 | I22: 7599 | J22: =SUM(C22:I22) -> 45628 | K22: =(J22-J21)/J21 -> -0.052732104 | L22: Memorial Day weekend
A23: 45803 | B23: 45809 | C23: 0 | D23: 0 | E23: 7149 | F23: 6069 | G23: 11483 | H23: 13634 | I23: 8915 | J23: =SUM(C23:I23) -> 47250 | K23: =(J23-J22)/J22 -> 0.035548348 | L23: Sunday event kick off summer
A24: 45810 | B24: 45816 | C24: 5029 | D24: 0 | E24: 6096 | F24: 6515.6 | G24: 14041 | H24: 11141 | I24: 9759 | J24: =SUM(C24:I24) -> 52581.6 | K24: =(J24-J23)/J23 -> 0.1128381 | L24: Good weather, lots new faces. First Fri lunch
A25: 45817 | B25: 45823 | C25: 2645 | D25: 3642 | E25: 7078 | F25: 7233 | G25: 11281 | H25: 13107 | I25: 11280 | J25: =SUM(C25:I25) -> 56266 | K25: =(J25-J24)/J24 -> 0.070070139 | L25: First Tuesday, change lunch to 1pm. First car show monday, Father's day walk ins
A26: 45824 | B26: 45830 | C26: 5699 | D26: 3610 | E26: 6183 | F26: 7379 | G26: 13357 | H26: 10515 | I26: 4292 | J26: =SUM(C26:I26) -> 51035 | K26: =(J26-J25)/J25 -> -0.092969111 | L26: Sunday super hot, Sat slow all day
A27: 45831 | B27: 45837 | C27: 7438 | D27: 4199 | E27: 5973 | F27: 6621 | G27: 13845 | H27: 10373 | I27: 6176 | J27: =SUM(C27:I27) -> 54625 | K27: =(J27-J26)/J26 -> 0.070343882
A28: 45838 | B28: 45844 | C28: 6375 | D28: 5681.21 | E28: 6488.35 | F28: 8029 | G28: 0 | H28: 12305 | I28: 6869 | J28: =SUM(C28:I28) -> 45747.56 | K28: =(J28-J27)/J27 -> -0.16251606 | L28: Closed for July 4th Friday, Mookie in BA. Heard downtown dead
A29: 45845 | B29: 45851 | C29: 6764 | D29: 5309 | E29: 7278 | F29: 5915 | G29: 14449 | H29: 13112 | I29: 11000 | J29: =SUM(C29:I29) -> 63827 | K29: =(J29-J28)/J28 -> 0.39520009 | L29: Bluegrass festival Sat, Sun, steady, patio packed, seemed slow though
A30: 45852 | B30: 45858 | C30: 5011 | D30: 5817 | E30: 5543 | F30: 6711 | G30: 16873 | H30: 13415 | I30: 6479 | J30: =SUM(C30:I30) -> 59849 | K30: =(J30-J29)/J29 -> -0.062324722 | L30: Big week, Friday steady all day
A31: 45859 | B31: 45865 | C31: 6081 | D31: 5745 | E31: 7414 | F31: 6358 | G31: 13744 | H31: 14022 | I31: 6742 | J31: =SUM(C31:I31) -> 60106 | K31: =(J31-J30)/J30 -> 0.0042941403 | L31: Niha bday Saturday, sophia manage
A32: 45866 | B32: 45872 | C32: 3918 | D32: 7936 | E32: 6008 | F32: 9240 | G32: 11730 | H32: 15364 | I32: 10282 | J32: =SUM(C32:I32) -> 64478 | K32: =(J32-J31)/J31 -> 0.072738163 | L32: Mookie out of town most of week, good weather, hot no rain, late crowds
A33: 45873 | B33: 45879 | C33: 6073 | D33: 5708 | E33: 6711 | F33: 8123 | G33: 13972 | H33: 15070 | I33: 8652 | J33: =SUM(C33:I33) -> 64309 | K33: =(J33-J32)/J32 -> -0.002621049
A34: 45880 | B34: 45886 | C34: 5197 | D34: 5086 | E34: 6911 | F34: 6886 | G34: 13693 | H34: 14804 | I34: 7394 | J34: =SUM(C34:I34) -> 59971 | K34: =(J34-J33)/J33 -> -0.067455566
A35: 45887 | B35: 45893 | C35: 3575 | D35: 4779 | E35: 5661 | F35: 6342 | G35: 15975 | H35: 16131 | I35: 9120.5 | J35: =SUM(C35:I35) -> 61583.5 | K35: =(J35-J34)/J34 -> 0.026887996 | L35: Monday school started back up. Wknd busy after slow week school, late rush Sunday
A36: 45894 | B36: 45900 | C36: 2698 | D36: 2947 | E36: 6142 | F36: 4241 | G36: 8497 | H36: 14041 | I36: 13380 | J36: =SUM(C36:I36) -> 51946 | K36: =(J36-J35)/J35 -> -0.15649484 | L36: Fall fest week slow. Friday slow. Not our crowd. Labor day early monday fest, died after 6:30. Refer to weekly sheet. Sunday busy
A37: 45901 | B37: 45907 | C37: 6449 | D37: 3456 | E37: 3635 | F37: 5991 | G37: 10842 | H37: 12760 | I37: 6012 | J37: =SUM(C37:I37) -> 49145 | K37: =(J37-J36)/J36 -> -0.05392138 | L37: great weather mid 70's windows open but sales slowing down.
A38: 45908 | B38: 45914 | C38: 2661 | D38: 2563.35 | E38: 5835.75 | F38: 5231 | G38: 12468 | H38: 15258 | I38: 5234.8 | J38: =SUM(C38:I38) -> 49251.9 | K38: =(J38-J37)/J37 -> 0.0021751958 | L38: Dancin Marlin said Sept slowest month due to school
A39: 45915 | B39: 45921 | C39: 3043 | D39: 3816 | E39: 4941 | F39: 4566 | G39: 13164 | H39: 11857 | I39: 4925 | J39: =SUM(C39:I39) -> 46312 | K39: =(J39-J38)/J38 -> -0.059691098 | L39: Slow week. Mookie in Spain all week. Niha/Sophia managed
A40: 45922 | B40: 45928 | C40: 3098 | D40: 3673 | E40: 5523 | F40: 4672 | G40: 14017 | H40: 15065 | I40: 6656 | J40: =SUM(C40:I40) -> 52704 | K40: =(J40-J39)/J39 -> 0.13802038 | L40: Wine Ale walk Sunday, decent weather
...

Sheet clean_weekly_data
A1: Week_Start | B1: Week_End | C1: Monday | D1: Tuesday | E1: Wednesday | F1: Thursday | G1: Friday | H1: Saturday | I1: Sunday | J1: Weekly_Total | K1: Weekly_Change_Pct | L1: Notes
A2: 45656 | B2: =A2+6 -> 45662 | C2: 7526.6 | D2: 0 | E2: 3689.55 | F2: 6453.51 | G2: 11241.1 | H2: 14053.74 | I2: 5195.91 | J2: 48160.4 | L2: Closed for NYE, Jan 1 slow
A3: =A2+7 -> 45663 | B3: =A3+6 -> 45669 | C3: 3232.85 | D3: 0 | E3: 4285 | F3: 4601.65 | G3: 9380.6 | H3: 14013.45 | I3: 3276.11 | J3: 38789.66 | K3: =(J3-J2)/J2 -> -0.19457355
A4: =A3+7 -> 45670 | B4: =A4+6 -> 45676 | C4: 2873.63 | D4: 0 | E4: 3636.3 | F4: 4807.4 | G4: 10376.25 | H4: 10088.6 | I4: 6109.2 | J4: 37891.38 | K4: =(J4-J3)/J3 -> -0.023157718
A5: =A4+7 -> 45677 | B5: =A5+6 -> 45683 | C5: 1724 | D5: 0 | E5: 2215.5 | F5: 4748.75 | G5: 12688.2 | H5: 14742.33 | I5: 3842.2 | J5: 39960.98 | K5: =(J5-J4)/J4 -> 0.054619283
A6: =A5+7 -> 45684 | B6: =A6+6 -> 45690 | C6: 3493.05 | D6: 0 | E6: 4034.15 | F6: 3766.75 | G6: 10237.15 | H6: 15657.91 | I6: 5008.25 | J6: 42197.26 | K6: =(J6-J5)/J5 -> 0.055961591 | L6: Dry January over, Fire and ice Chili cookoff social Downtown Sat Feb 1
A7: =A6+7 -> 45691 | B7: =A7+6 -> 45697 | C7: 2809.11 | D7: 4391 | E7: 3380.3 | F7: 4906 | G7: 8830.45 | H7: 12087.75 | I7: 1122 | J7: 37526.61 | K7: =(J7-J6)/J6 -> -0.1106861
A8: =A7+7 -> 45698 | B8: =A8+6 -> 45704 | C8: 1424 | D8: 0 | E8: 1854 | F8: 6612 | G8: 16427 | H8: 15530 | I8: 7548 | J8: =SUM(C8:I8) -> 49395 | K8: =(J8-J7)/J7 -> 0.31626598 | L8: Hide main hours to book pre/post center
A9: =A8+7 -> 45705 | B9: =A9+6 -> 45711 | C9: 1873 | D9: 0 | E9: 3576 | F9: 3388 | G9: 10389 | H9: 13440 | I9: 4428 | J9: =SUM(C9:I9) -> 37094 | K9: =(J9-J8)/J8 -> -0.2490333 | L9: Chocolate walk sunday was ok
A10: =A9+7 -> 45712 | B10: =A10+6 -> 45718 | C10: 2144 | D10: 0 | E10: 2466 | F10: 5886 | G10: 10886 | H10: 13701 | I10: 5490 | J10: =SUM(C10:I10) -> 40573 | K10: =(J10-J9)/J9 -> 0.093788753
A11: =A10+7 -> 45719 | B11: =A11+6 -> 45725 | C11: 1961 | D11: 0 | E11: 3458 | F11: 2996.6 | G11: 10998 | H11: 12545 | I11: 5549 | J11: =SUM(C11:I11) -> 37507.6 | K11: =(J11-J10)/J10 -> -0.075552707
A12: =A11+7 -> 45726 | B12: =A12+6 -> 45732 | C12: 4895 | D12: 0 | E12: 4403 | F12: 2945 | G12: 10542 | H12: 11247 | I12: 3112 | J12: =SUM(C12:I12) -> 37144 | K12: =(J12-J11)/J11 -> -0.0096940353
A13: =A12+7 -> 45733 | B13: =A13+6 -> 45739 | C13: 3681 | D13: 0 | E13: 4574 | F13: 4023 | G13: 11199 | H13: 14365 | I13: 5519 | J13: =SUM(C13:I13) -> 43361 | K13: =(J13-J12)/J12 -> 0.16737562
A14: =A13+7 -> 45740 | B14: =A14+6 -> 45746 | C14: 2821 | D14: 0 | E14: 4872 | F14: 3809 | G14: 11848 | H14: 12858 | I14: 7089 | J14: =SUM(C14:I14) -> 43297 | K14: =(J14-J13)/J13 -> -0.0014759807
A15: =A14+7 -> 45747 | B15: =A15+6 -> 45753 | C15: 3355 | D15: 0 | E15: 3614 | F15: 4382 | G15: 10897 | H15: 11210 | I15: 6114.5 | J15: =SUM(C15:I15) -> 39572.5 | K15: =(J15-J14)/J14 -> -0.086022126
A16: =A15+7 -> 45754 | B16: =A16+6 -> 45760 | C16: 2556 | D16: 0 | E16: 2715 | F16: 5123 | G16: 9878 | H16: 12989 | I16: 4164 | J16: =SUM(C16:I16) -> 37425 | K16: =(J16-J15)/J15 -> -0.054267484
A17: =A16+7 -> 45761 | B17: =A17+6 -> 45767 | C17: 3225 | D17: 0 | E17: 3603 | F17: 4944 | G17: 11764 | H17: 11381 | I17: 2925 | J17: =SUM(C17:I17) -> 37842 | K17: =(J17-J16)/J16 -> 0.011142285 | L17: Easter Sunday dead
A18: =A17+7 -> 45768 | B18: =A18+6 -> 45774 | C18: 2902 | D18: 0 | E18: 3032 | F18: 4640 | G18: 10664 | H18: 11291 | I18: 2941 | J18: =SUM(C18:I18) -> 35470 | K18: =(J18-J17)/J17 -> -0.062681676
A19: =A18+7 -> 45775 | B19: =A19+6 -> 45781 | C19: 2822 | D19: 0 | E19: 2386 | F19: 6288 | G19: 11945 | H19: 12110 | I19: 4341 | J19: =SUM(C19:I19) -> 39892 | K19: =(J19-J18)/J18 -> 0.12466873 | L19: Opened patio
A20: =A19+7 -> 45782 | B20: =A20+6 -> 45788 | C20: 1474 | D20: 0 | E20: 4041 | F20: 3588 | G20: 11708 | H20: 14558 | I20: 15587.75 | J20: =SUM(C20:I20) -> 50956.75 | K20: =(J20-J19)/J19 -> 0.27736764 | L20: Mother's day, graduation week, nice weather
A21: =A20+7 -> 45789 | B21: =A21+6 -> 45795 | C21: 3653 | D21: 0 | E21: 4927 | F21: 5650 | G21: 11726 | H21: 13835 | I21: 8377 | J21: =SUM(C21:I21) -> 48168 | K21: =(J21-J20)/J20 -> -0.054727784 | L21: Good weather/ wind Thurs/Fri, Graduation Sat
A22: =A21+7 -> 45796 | B22: =A22+6 -> 45802 | C22: 3299 | D22: 0 | E22: 5200 | F22: 4369 | G22: 14274 | H22: 10887 | I22: 7599 | J22: =SUM(C22:I22) -> 45628 | K22: =(J22-J21)/J21 -> -0.052732104 | L22: Memorial Day weekend
A23: =A22+7 -> 45803 | B23: =A23+6 -> 45809 | C23: 0 | D23: 0 | E23: 7149 | F23: 6069 | G23: 11483 | H23: 13634 | I23: 8915 | J23: =SUM(C23:I23) -> 47250 | K23: =(J23-J22)/J22 -> 0.035548348 | L23: Sunday event kick off summer
A24: =A23+7 -> 45810 | B24: =A24+6 -> 45816 | C24: 5029 | D24: 0 | E24: 6096 | F24: 6515.6 | G24: 14041 | H24: 11141 | I24: 9759 | J24: =SUM(C24:I24) -> 52581.6 | K24: =(J24-J23)/J23 -> 0.1128381 | L24: Good weather, lots new faces. First Fri lunch
A25: =A24+7 -> 45817 | B25: =A25+6 -> 45823 | C25: 2645 | D25: 3642 | E25: 7078 | F25: 7233 | G25: 11281 | H25: 13107 | I25: 11280 | J25: =SUM(C25:I25) -> 56266 | K25: =(J25-J24)/J24 -> 0.070070139 | L25: First Tuesday, change lunch to 1pm. First car show monday, Father's day walk ins
A26: =A25+7 -> 45824 | B26: =A26+6 -> 45830 | C26: 5699 | D26: 3610 | E26: 6183 | F26: 7379 | G26: 13357 | H26: 10515 | I26: 4292 | J26: =SUM(C26:I26) -> 51035 | K26: =(J26-J25)/J25 -> -0.092969111 | L26: Sunday super hot, Sat slow all day
A27: =A26+7 -> 45831 | B27: =A27+6 -> 45837 | C27: 7438 | D27: 4199 | E27: 5973 | F27: 6621 | G27: 13845 | H27: 10373 | I27: 6176 | J27: =SUM(C27:I27) -> 54625 | K27: =(J27-J26)/J26 -> 0.070343882
A28: =A27+7 -> 45838 | B28: =A28+6 -> 45844 | C28: 6375 | D28: 5681.21 | E28: 6488.35 | F28: 8029 | G28: 0 | H28: 12305 | I28: 6869 | J28: =SUM(C28:I28) -> 45747.56 | K28: =(J28-J27)/J27 -> -0.16251606 | L28: Closed for July 4th Friday, Mookie in BA. Heard downtown dead
A29: =A28+7 -> 45845 | B29: =A29+6 -> 45851 | C29: 6764 | D29: 5309 | E29: 7278 | F29: 5915 | G29: 14449 | H29: 13112 | I29: 11000 | J29: =SUM(C29:I29) -> 63827 | K29: =(J29-J28)/J28 -> 0.39520009 | L29: Bluegrass festival Sat, Sun, steady, patio packed, seemed slow though
A30: =A29+7 -> 45852 | B30: =A30+6 -> 45858 | C30: 5011 | D30: 5817 | E30: 5543 | F30: 6711 | G30: 16873 | H30: 13415 | I30: 6479 | J30: =SUM(C30:I30) -> 59849 | K30: =(J30-J29)/J29 -> -0.062324722 | L30: Big week, Friday steady all day
A31: =A30+7 -> 45859 | B31: =A31+6 -> 45865 | C31: 6081 | D31: 5745 | E31: 7414 | F31: 6358 | G31: 13744 | H31: 14022 | I31: 6742 | J31: =SUM(C31:I31) -> 60106 | K31: =(J31-J30)/J30 -> 0.0042941403 | L31: Niha bday Saturday, sophia manage
A32: =A31+7 -> 45866 | B32: =A32+6 -> 45872 | C32: 3918 | D32: 7936 | E32: 6008 | F32: 9240 | G32: 11730 | H32: 15364 | I32: 10282 | J32: =SUM(C32:I32) -> 64478 | K32: =(J32-J31)/J31 -> 0.072738163 | L32: Mookie out of town most of week, good weather, hot no rain, late crowds
A33: =A32+7 -> 45873 | B33: =A33+6 -> 45879 | C33: 6073 | D33: 5708 | E33: 6711 | F33: 8123 | G33: 13972 | H33: 15070 | I33: 8652 | J33: =SUM(C33:I33) -> 64309 | K33: =(J33-J32)/J32 -> -0.002621049
A34: =A33+7 -> 45880 | B34: =A34+6 -> 45886 | C34: 5197 | D34: 5086 | E34: 6911 | F34: 6886 | G34: 13693 | H34: 14804 | I34: 7394 | J34: =SUM(C34:I34) -> 59971 | K34: =(J34-J33)/J33 -> -0.067455566
A35: =A34+7 -> 45887 | B35: =A35+6 -> 45893 | C35: 3575 | D35: 4779 | E35: 5661 | F35: 6342 | G35: 15975 | H35: 16131 | I35: 9120.5 | J35: =SUM(C35:I35) -> 61583.5 | K35: =(J35-J34)/J34 -> 0.026887996 | L35: Monday school started back up. Wknd busy after slow week school, late rush Sunday
A36: =A35+7 -> 45894 | B36: =A36+6 -> 45900 | C36: 2698 | D36: 2947 | E36: 6142 | F36: 4241 | G36: 8497 | H36: 14041 | I36: 13380 | J36: =SUM(C36:I36) -> 51946 | K36: =(J36-J35)/J35 -> -0.15649484 | L36: Fall fest week slow. Friday slow. Not our crowd. Labor day early monday fest, died after 6:30. Refer to weekly sheet. Sunday busy
A37: =A36+7 -> 45901 | B37: =A37+6 -> 45907 | C37: 6449 | D37: 3456 | E37: 3635 | F37: 5991 | G37: 10842 | H37: 12760 | I37: 6012 | J37: =SUM(C37:I37) -> 49145 | K37: =(J37-J36)/J36 -> -0.05392138 | L37: great weather mid 70's windows open but sales slowing down.
A38: =A37+7 -> 45908 | B38: =A38+6 -> 45914 | C38: 2661 | D38: 2563.35 | E38: 5835.75 | F38: 5231 | G38: 12468 | H38: 15258 | I38: 5234.8 | J38: =SUM(C38:I38) -> 49251.9 | K38: =(J38-J37)/J37 -> 0.0021751958 | L38: Dancin Marlin said Sept slowest month due to school
A39: =A38+7 -> 45915 | B39: =A39+6 -> 45921 | C39: 3043 | D39: 3816 | E39: 4941 | F39: 4566 | G39: 13164 | H39: 11857 | I39: 4925 | J39: =SUM(C39:I39) -> 46312 | K39: =(J39-J38)/J38 -> -0.059691098 | L39: Slow week. Mookie in Spain all week. Niha/Sophia managed
A40: =A39+7 -> 45922 | B40: =A40+6 -> 45928 | C40: 3098 | D40: 3673 | E40: 5523 | F40: 4672 | G40: 14017 | H40: 15065 | I40: 6656 | J40: =SUM(C40:I40) -> 52704 | K40: =(J40-J39)/J39 -> 0.13802038 | L40: Wine Ale walk Sunday, decent weather
...

Sheet clean_monthly_summary
A1: Month_Year | B1: Net_Sales | C1: Tax Payment | D1: Projected_Value | E1: Variance | F1: Rolling_Variance | G1: Month_Label | H1: Month_Sort
A2: 45658 | B2: =SUMIF(daily_sales_helper!$D:$D,A2,daily_sales_helper!$C:$C) -> 178806.93 | C2: =B2*$B$18 -> 14304.554 | D2: 187244 | E2: =B2-D2 -> -8437.07 | F2: =E2 -> -8437.07 | G2: =TEXT(tblMonthlySummary[[#This Row],[Month_Year]],"mmm yyyy") -> Jan 2025 | H2: =tblMonthlySummary[[#This Row],[Month_Year]] -> 45658
A3: 45689 | B3: =SUMIF(daily_sales_helper!$D:$D,A3,daily_sales_helper!$C:$C) -> 166063.77 | C3: =B3*$B$18 -> 13285.102 | D3: 187244 | E3: =B3-D3 -> -21180.23 | F3: =F2+E3 -> -29617.3 | G3: =TEXT(tblMonthlySummary[[#This Row],[Month_Year]],"mmm yyyy") -> Feb 2025 | H3: =tblMonthlySummary[[#This Row],[Month_Year]] -> 45689
A4: 45717 | B4: =SUMIF(daily_sales_helper!$D:$D,A4,daily_sales_helper!$C:$C) -> 183855.6 | C4: =B4*$B$18 -> 14708.448 | D4: 187244 | E4: =B4-D4 -> -3388.4 | F4: =F3+E4 -> -33005.7 | G4: =TEXT(tblMonthlySummary[[#This Row],[Month_Year]],"mmm yyyy") -> Mar 2025 | H4: =tblMonthlySummary[[#This Row],[Month_Year]] -> 45717
A5: 45748 | B5: =SUMIF(daily_sales_helper!$D:$D,A5,daily_sales_helper!$C:$C) -> 152162.5 | C5: =B5*$B$18 -> 12173 | D5: 187244 | E5: =B5-D5 -> -35081.5 | F5: =F4+E5 -> -68087.2 | G5: =TEXT(tblMonthlySummary[[#This Row],[Month_Year]],"mmm yyyy") -> Apr 2025 | H5: =tblMonthlySummary[[#This Row],[Month_Year]] -> 45748
A6: 45778 | B6: =SUMIF(daily_sales_helper!$D:$D,A6,daily_sales_helper!$C:$C) -> 217771.75 | C6: =B6*$B$18 -> 17421.74 | D6: 187244 | E6: =B6-D6 -> 30527.75 | F6: =F5+E6 -> -37559.45 | G6: =TEXT(tblMonthlySummary[[#This Row],[Month_Year]],"mmm yyyy") -> May 2025 | H6: =tblMonthlySummary[[#This Row],[Month_Year]] -> 45778
A7: 45809 | B7: =SUMIF(daily_sales_helper!$D:$D,A7,daily_sales_helper!$C:$C) -> 229797.6 | C7: =B7*$B$18 -> 18383.808 | D7: 201393 | E7: =B7-D7 -> 28404.6 | F7: =F6+E7 -> -9154.85 | G7: =TEXT(tblMonthlySummary[[#This Row],[Month_Year]],"mmm yyyy") -> Jun 2025 | H7: =tblMonthlySummary[[#This Row],[Month_Year]] -> 45809
A8: 45839 | B8: =SUMIF(daily_sales_helper!$D:$D,A8,daily_sales_helper!$C:$C) -> 250256.56 | C8: =B8*$B$18 -> 20020.525 | D8: 201393 | E8: =B8-D8 -> 48863.56 | F8: =F7+E8 -> 39708.71 | G8: =TEXT(tblMonthlySummary[[#This Row],[Month_Year]],"mmm yyyy") -> Jul 2025 | H8: =tblMonthlySummary[[#This Row],[Month_Year]] -> 45839
A9: 45870 | B9: =SUMIF(daily_sales_helper!$D:$D,A9,daily_sales_helper!$C:$C) -> 275185.5 | C9: =B9*$B$18 -> 22014.84 | D9: 201393 | E9: =B9-D9 -> 73792.5 | F9: =F8+E9 -> 113501.21 | G9: =TEXT(tblMonthlySummary[[#This Row],[Month_Year]],"mmm yyyy") -> Aug 2025 | H9: =tblMonthlySummary[[#This Row],[Month_Year]] -> 45870
A10: 45901 | B10: =SUMIF(daily_sales_helper!$D:$D,A10,daily_sales_helper!$C:$C) -> 206815.9 | C10: =B10*$B$18 -> 16545.272 | D10: 201393 | E10: =B10-D10 -> 5422.9 | F10: =F9+E10 -> 118924.11 | G10: =TEXT(tblMonthlySummary[[#This Row],[Month_Year]],"mmm yyyy") -> Sep 2025 | H10: =tblMonthlySummary[[#This Row],[Month_Year]] -> 45901
A11: 45931 | B11: =SUMIF(daily_sales_helper!$D:$D,A11,daily_sales_helper!$C:$C) -> 196713.35 | C11: =B11*$B$18 -> 15737.068 | D11: 201393 | E11: =B11-D11 -> -4679.65 | F11: =F10+E11 -> 114244.46 | G11: =TEXT(tblMonthlySummary[[#This Row],[Month_Year]],"mmm yyyy") -> Oct 2025 | H11: =tblMonthlySummary[[#This Row],[Month_Year]] -> 45931
A12: 45962 | B12: =SUMIF(daily_sales_helper!$D:$D,A12,daily_sales_helper!$C:$C) -> 176875 | C12: =B12*$B$18 -> 14150 | D12: 187244 | E12: =B12-D12 -> -10369 | F12: =F11+E12 -> 103875.46 | G12: =TEXT(tblMonthlySummary[[#This Row],[Month_Year]],"mmm yyyy") -> Nov 2025 | H12: =tblMonthlySummary[[#This Row],[Month_Year]] -> 45962
A13: 45992 | B13: =SUMIF(daily_sales_helper!$D:$D,A13,daily_sales_helper!$C:$C) -> 184002 | C13: =B13*$B$18 -> 14720.16 | D13: 187244 | E13: =B13-D13 -> -3242 | F13: =F12+E13 -> 100633.46 | G13: =TEXT(tblMonthlySummary[[#This Row],[Month_Year]],"mmm yyyy") -> Dec 2025 | H13: =tblMonthlySummary[[#This Row],[Month_Year]] -> 45992
A14: 46023 | B14: =SUMIF(daily_sales_helper!$D:$D,A14,daily_sales_helper!$C:$C) -> 188741 | C14: =B14*$B$18 -> 15099.28 | D14: 187244 | E14: =B14-D14 -> 1497 | F14: =F13+E14 -> 102130.46 | G14: =TEXT(tblMonthlySummary[[#This Row],[Month_Year]],"mmm yyyy") -> Jan 2026 | H14: =tblMonthlySummary[[#This Row],[Month_Year]] -> 46023
A15: 46054 | B15: =SUMIF(daily_sales_helper!$D:$D,A15,daily_sales_helper!$C:$C) -> 181065 | C15: =B15*$B$18 -> 14485.2 | D15: 187244 | E15: =B15-D15 -> -6179 | F15: =F14+E15 -> 95951.46 | G15: =TEXT(tblMonthlySummary[[#This Row],[Month_Year]],"mmm yyyy") -> Feb 2026 | H15: =tblMonthlySummary[[#This Row],[Month_Year]] -> 46054
A16: Total | B16: =SUM(B2:B15) -> 2788112.5 | C16: =SUM(C2:C15) -> 223049 | D16: =SUM(D2:D15) -> 2692161 | E16: =SUM(E2:E15) -> 95951.46 | F16: =SUM(F2:F15) -> 603107.76 | G16: =TEXT(tblMonthlySummary[[#This Row],[Month_Year]],"mmm yyyy") -> Total | H16: =tblMonthlySummary[[#This Row],[Month_Year]] -> Total
A18: N.B: Tax Rate = | B18: 0.08

Sheet daily_sales_helper
A1: Sale_Date | B1: Day_Name | C1: Sales | D1: Month_Year | E1: Weekly_Row_Source
A2: {=INDEX(clean_weekly_data!$A:$A,$E2)+MOD(ROW()-2,7)} -> 45656 | B2: =CHOOSE(MOD(ROW()-2,7)+1,"Monday","Tuesday","Wednesday","Thursday","Friday","Saturday","Sunday") -> Monday | C2: {=INDEX(clean_weekly_data!$C:$I,$E2,MOD(ROW()-2,7)+1)} -> 7526.6 | D2: =TEXT(A2,"mmm yyyy") -> Dec 2024 | E2: =INT((ROW()-2)/7)+2 -> 2
A3: {=INDEX(clean_weekly_data!$A:$A,$E3)+MOD(ROW()-2,7)} -> 45657 | B3: =CHOOSE(MOD(ROW()-2,7)+1,"Monday","Tuesday","Wednesday","Thursday","Friday","Saturday","Sunday") -> Tuesday | C3: {=INDEX(clean_weekly_data!$C:$I,$E3,MOD(ROW()-2,7)+1)} -> 0 | D3: =TEXT(A3,"mmm yyyy") -> Dec 2024 | E3: =INT((ROW()-2)/7)+2 -> 2
A4: {=INDEX(clean_weekly_data!$A:$A,$E4)+MOD(ROW()-2,7)} -> 45658 | B4: =CHOOSE(MOD(ROW()-2,7)+1,"Monday","Tuesday","Wednesday","Thursday","Friday","Saturday","Sunday") -> Wednesday | C4: {=INDEX(clean_weekly_data!$C:$I,$E4,MOD(ROW()-2,7)+1)} -> 3689.55 | D4: =TEXT(A4,"mmm yyyy") -> Jan 2025 | E4: =INT((ROW()-2)/7)+2 -> 2
A5: {=INDEX(clean_weekly_data!$A:$A,$E5)+MOD(ROW()-2,7)} -> 45659 | B5: =CHOOSE(MOD(ROW()-2,7)+1,"Monday","Tuesday","Wednesday","Thursday","Friday","Saturday","Sunday") -> Thursday | C5: {=INDEX(clean_weekly_data!$C:$I,$E5,MOD(ROW()-2,7)+1)} -> 6453.51 | D5: =TEXT(A5,"mmm yyyy") -> Jan 2025 | E5: =INT((ROW()-2)/7)+2 -> 2
A6: {=INDEX(clean_weekly_data!$A:$A,$E6)+MOD(ROW()-2,7)} -> 45660 | B6: =CHOOSE(MOD(ROW()-2,7)+1,"Monday","Tuesday","Wednesday","Thursday","Friday","Saturday","Sunday") -> Friday | C6: {=INDEX(clean_weekly_data!$C:$I,$E6,MOD(ROW()-2,7)+1)} -> 11241.1 | D6: =TEXT(A6,"mmm yyyy") -> Jan 2025 | E6: =INT((ROW()-2)/7)+2 -> 2
A7: {=INDEX(clean_weekly_data!$A:$A,$E7)+MOD(ROW()-2,7)} -> 45661 | B7: =CHOOSE(MOD(ROW()-2,7)+1,"Monday","Tuesday","Wednesday","Thursday","Friday","Saturday","Sunday") -> Saturday | C7: {=INDEX(clean_weekly_data!$C:$I,$E7,MOD(ROW()-2,7)+1)} -> 14053.74 | D7: =TEXT(A7,"mmm yyyy") -> Jan 2025 | E7: =INT((ROW()-2)/7)+2 -> 2
A8: {=INDEX(clean_weekly_data!$A:$A,$E8)+MOD(ROW()-2,7)} -> 45662 | B8: =CHOOSE(MOD(ROW()-2,7)+1,"Monday","Tuesday","Wednesday","Thursday","Friday","Saturday","Sunday") -> Sunday | C8: {=INDEX(clean_weekly_data!$C:$I,$E8,MOD(ROW()-2,7)+1)} -> 5195.91 | D8: =TEXT(A8,"mmm yyyy") -> Jan 2025 | E8: =INT((ROW()-2)/7)+2 -> 2
A9: {=INDEX(clean_weekly_data!$A:$A,$E9)+MOD(ROW()-2,7)} -> 45663 | B9: =CHOOSE(MOD(ROW()-2,7)+1,"Monday","Tuesday","Wednesday","Thursday","Friday","Saturday","Sunday") -> Monday | C9: {=INDEX(clean_weekly_data!$C:$I,$E9,MOD(ROW()-2,7)+1)} -> 3232.85 | D9: =TEXT(A9,"mmm yyyy") -> Jan 2025 | E9: =INT((ROW()-2)/7)+2 -> 3
A10: {=INDEX(clean_weekly_data!$A:$A,$E10)+MOD(ROW()-2,7)} -> 45664 | B10: =CHOOSE(MOD(ROW()-2,7)+1,"Monday","Tuesday","Wednesday","Thursday","Friday","Saturday","Sunday") -> Tuesday | C10: {=INDEX(clean_weekly_data!$C:$I,$E10,MOD(ROW()-2,7)+1)} -> 0 | D10: =TEXT(A10,"mmm yyyy") -> Jan 2025 | E10: =INT((ROW()-2)/7)+2 -> 3
A11: {=INDEX(clean_weekly_data!$A:$A,$E11)+MOD(ROW()-2,7)} -> 45665 | B11: =CHOOSE(MOD(ROW()-2,7)+1,"Monday","Tuesday","Wednesday","Thursday","Friday","Saturday","Sunday") -> Wednesday | C11: {=INDEX(clean_weekly_data!$C:$I,$E11,MOD(ROW()-2,7)+1)} -> 4285 | D11: =TEXT(A11,"mmm yyyy") -> Jan 2025 | E11: =INT((ROW()-2)/7)+2 -> 3
A12: {=INDEX(clean_weekly_data!$A:$A,$E12)+MOD(ROW()-2,7)} -> 45666 | B12: =CHOOSE(MOD(ROW()-2,7)+1,"Monday","Tuesday","Wednesday","Thursday","Friday","Saturday","Sunday") -> Thursday | C12: {=INDEX(clean_weekly_data!$C:$I,$E12,MOD(ROW()-2,7)+1)} -> 4601.65 | D12: =TEXT(A12,"mmm yyyy") -> Jan 2025 | E12: =INT((ROW()-2)/7)+2 -> 3
A13: {=INDEX(clean_weekly_data!$A:$A,$E13)+MOD(ROW()-2,7)} -> 45667 | B13: =CHOOSE(MOD(ROW()-2,7)+1,"Monday","Tuesday","Wednesday","Thursday","Friday","Saturday","Sunday") -> Friday | C13: {=INDEX(clean_weekly_data!$C:$I,$E13,MOD(ROW()-2,7)+1)} -> 9380.6 | D13: =TEXT(A13,"mmm yyyy") -> Jan 2025 | E13: =INT((ROW()-2)/7)+2 -> 3
... A442: {=INDEX(clean_weekly_data!$A:$A,$E442)+MOD(ROW()-2,7)} -> 46096 | B442: =CHOOSE(MOD(ROW()-2,7)+1,"Monday","Tuesday","Wednesday","Thursday","Friday","Saturday","Sunday") -> Sunday | C442: {=INDEX(clean_weekly_data!$C:$I,$E442,MOD(ROW()-2,7)+1)} -> 0 | D442: =TEXT(A442,"mmm yyyy") -> Mar 2026 | E442: =INT((ROW()-2)/7)+2 -> 64

Sheet dashboard
B1: Sales Performance and Variance Analysis Dashboard
B3: Performance Summary | AG3: Month | AH3: Actual_Sales | AI3: Projected_Sales | AJ3: Variance | AK3: Rolling_Variance
AG4: =TEXT(clean_monthly_summary!A2,"mmm yyyy") -> Jan 2025 | AH4: =clean_monthly_summary!B2 -> 178806.93 | AI4: =clean_monthly_summary!D2 -> 187244 | AJ4: =clean_monthly_summary!E2 -> -8437.07 | AK4: =clean_monthly_summary!F2 -> -8437.07
B5: Total Net Sales | F5: Average Monthly Sales | J5: Best Month | N5: Worst Month | R5: Final Rolling Variance | AG5: =TEXT(clean_monthly_summary!A3,"mmm yyyy") -> Feb 2025 | AH5: =clean_monthly_summary!B3 -> 166063.77 | AI5: =clean_monthly_summary!D3 -> 187244 | AJ5: =clean_monthly_summary!E3 -> -21180.23 | AK5: =clean_monthly_summary!F3 -> -29617.3
B6: =SUM(clean_monthly_summary!B2:B15) -> 2788112.5 | F6: =AVERAGE(clean_monthly_summary!B2:B15) -> 199150.89 | J6: =TEXT(INDEX(clean_monthly_summary!A2:A15,MATCH(MAX(clean_monthly_summary!B2:B15),clean_monthly_summary!B2:B15,0)),"mmm yyyy") -> Aug 2025 | N6: =TEXT(INDEX(clean_monthly_summary!A2:A15,MATCH(MIN(clean_monthly_summary!B2:B15),clean_monthly_summary!B2:B15,0)),"mmm yyyy") -> Apr 2025 | R6: =clean_monthly_summary!F15 -> 95951.46 | AG6: =TEXT(clean_monthly_summary!A4,"mmm yyyy") -> Mar 2025 | AH6: =clean_monthly_summary!B4 -> 183855.6 | AI6: =clean_monthly_summary!D4 -> 187244 | AJ6: =clean_monthly_summary!E4 -> -3388.4 | AK6: =clean_monthly_summary!F4 -> -33005.7
J7: =MAX(clean_monthly_summary!B2:B15) -> 275185.5 | N7: =MIN(clean_monthly_summary!B2:B15) -> 152162.5 | AG7: =TEXT(clean_monthly_summary!A5,"mmm yyyy") -> Apr 2025 | AH7: =clean_monthly_summary!B5 -> 152162.5 | AI7: =clean_monthly_summary!D5 -> 187244 | AJ7: =clean_monthly_summary!E5 -> -35081.5 | AK7: =clean_monthly_summary!F5 -> -68087.2
AG8: =TEXT(clean_monthly_summary!A6,"mmm yyyy") -> May 2025 | AH8: =clean_monthly_summary!B6 -> 217771.75 | AI8: =clean_monthly_summary!D6 -> 187244 | AJ8: =clean_monthly_summary!E6 -> 30527.75 | AK8: =clean_monthly_summary!F6 -> -37559.45
AG9: =TEXT(clean_monthly_summary!A7,"mmm yyyy") -> Jun 2025 | AH9: =clean_monthly_summary!B7 -> 229797.6 | AI9: =clean_monthly_summary!D7 -> 201393 | AJ9: =clean_monthly_summary!E7 -> 28404.6 | AK9: =clean_monthly_summary!F7 -> -9154.85
AG10: =TEXT(clean_monthly_summary!A8,"mmm yyyy") -> Jul 2025 | AH10: =clean_monthly_summary!B8 -> 250256.56 | AI10: =clean_monthly_summary!D8 -> 201393 | AJ10: =clean_monthly_summary!E8 -> 48863.56 | AK10: =clean_monthly_summary!F8 -> 39708.71
AG11: =TEXT(clean_monthly_summary!A9,"mmm yyyy") -> Aug 2025 | AH11: =clean_monthly_summary!B9 -> 275185.5 | AI11: =clean_monthly_summary!D9 -> 201393 | AJ11: =clean_monthly_summary!E9 -> 73792.5 | AK11: =clean_monthly_summary!F9 -> 113501.21
AG12: =TEXT(clean_monthly_summary!A10,"mmm yyyy") -> Sep 2025 | AH12: =clean_monthly_summary!B10 -> 206815.9 | AI12: =clean_monthly_summary!D10 -> 201393 | AJ12: =clean_monthly_summary!E10 -> 5422.9 | AK12: =clean_monthly_summary!F10 -> 118924.11
AG13: =TEXT(clean_monthly_summary!A11,"mmm yyyy") -> Oct 2025 | AH13: =clean_monthly_summary!B11 -> 196713.35 | AI13: =clean_monthly_summary!D11 -> 201393 | AJ13: =clean_monthly_summary!E11 -> -4679.65 | AK13: =clean_monthly_summary!F11 -> 114244.46
AG14: =TEXT(clean_monthly_summary!A12,"mmm yyyy") -> Nov 2025 | AH14: =clean_monthly_summary!B12 -> 176875 | AI14: =clean_monthly_summary!D12 -> 187244 | AJ14: =clean_monthly_summary!E12 -> -10369 | AK14: =clean_monthly_summary!F12 -> 103875.46
AG15: =TEXT(clean_monthly_summary!A13,"mmm yyyy") -> Dec 2025 | AH15: =clean_monthly_summary!B13 -> 184002 | AI15: =clean_monthly_summary!D13 -> 187244 | AJ15: =clean_monthly_summary!E13 -> -3242 | AK15: =clean_monthly_summary!F13 -> 100633.46
AG16: =TEXT(clean_monthly_summary!A14,"mmm yyyy") -> Jan 2026 | AH16: =clean_monthly_summary!B14 -> 188741 | AI16: =clean_monthly_summary!D14 -> 187244 | AJ16: =clean_monthly_summary!E14 -> 1497 | AK16: =clean_monthly_summary!F14 -> 102130.46
AG17: =TEXT(clean_monthly_summary!A15,"mmm yyyy") -> Feb 2026 | AH17: =clean_monthly_summary!B15 -> 181065 | AI17: =clean_monthly_summary!D15 -> 187244 | AJ17: =clean_monthly_summary!E15 -> -6179 | AK17: =clean_monthly_summary!F15 -> 95951.46
AG22: Day_Name | AH22: Average_Sales
AG23: Monday | AH23: =AVERAGEIF(daily_sales_helper!$B:$B,AG23,daily_sales_helper!$C:$C) -> 3631.7181
AG24: Tuesday | AH24: =AVERAGEIF(daily_sales_helper!$B:$B,AG24,daily_sales_helper!$C:$C) -> 2332.6279
AG25: Wednesday | AH25: =AVERAGEIF(daily_sales_helper!$B:$B,AG25,daily_sales_helper!$C:$C) -> 4337.9984
AG26: Thursday | AH26: =AVERAGEIF(daily_sales_helper!$B:$B,AG26,daily_sales_helper!$C:$C) -> 5011.1525
AG27: Friday | AH27: =AVERAGEIF(daily_sales_helper!$B:$B,AG27,daily_sales_helper!$C:$C) -> 11653.012
AG28: Saturday | AH28: =AVERAGEIF(daily_sales_helper!$B:$B,AG28,daily_sales_helper!$C:$C) -> 12684.044
AG29: Sunday | AH29: =AVERAGEIF(daily_sales_helper!$B:$B,AG29,daily_sales_helper!$C:$C) -> 5954.7495

Sheet analaysis_summary
B1: Analaysis Summary
B2: Weekly sales performance review covering Jan 2025 to Feb 2026, focused on target variance, cumulative recovery, and weekday revenue structure.
B5: Performance Summary
B7: 1 | C7: Sales underperformed target in the early part of 2025, with April 2025 emerging as the weakest full month.
B8: 2 | C8: Performance recovered strongly from June to September 2025, with August 2025 delivering the highest monthly sales and strongest positive variance.
B9: 3 | C9: Rolling variance moved from a negative position into sustained positive territory by mid 2025, indicating cumulative recovery against target.
B10: 4 | C10: Revenue is concentrated toward the end of the week, with Friday and Saturday producing the highest average daily sales, suggesting strong weekend dependence.
B13: Business Implications
B14: 1 | C14: Early week demand appears comparatively weak and may represent an opportunity for targeted sales improvement.
B15: 2 | C15: End of week concentration suggests that operational disruptions on Friday or Saturday could have disproportionate revenue impact.
B16: 3 | C16: Rolling variance is a stronger measure of recovery than single month performance because it shows whether gains are cumulative.
B17: 4 | C17: The mid 2025 uplift appears to reflect a genuine improvement phase rather than random fluctuation.

Sheet Weekly Rating
F1: 45819 | H1: =F1+7 -> 45826 | J1: =H1+7 -> 45833 | L1: =J1+7 -> 45840 | N1: =L1+7 -> 45847
B2: Description | C2: 45798 | D2: 45805 | E2: 45812 | F2: FOH | G2: BOH | H2: FOH | I2: BOH | J2: FOH | K2: BOH | L2: FOH | M2: BOH | N2: FOH | O2: BOH
A3: Accountability | B3: Keeping each other and ourselves accountable for our roles, responsibilites and areas of improvement? Are we checking up on each other holding each other to expectations? | C3: 2 | D3: 7 | E3: 7.5 | F3: 7.5 | G3: 6.5 | H3: 8 | I3: 8
A4: Communication | B4: Are we communicating with each other and down to our staff about expectations, changes, improvements, needing help, etc | C4: 6 | D4: 6 | E4: 2 | F4: 8 | G4: 7 | H4: 8 | I4: 8
A5: Consistency | B5: Are we showing consistency in our respective areas? Performance, deliverables, sushi rolls, prep, FOH, routines, checklist items | C5: 3 | D5: 6 | E5: 8 | F5: 7 | G5: 7 | H5: 5.5 | I5: 5.5
A6: Structure / process | B6: Are we and staff following the processes and structure we have in place? | C6: 1 | D6: 7 | E6: =AVERAGE(8,6,7,6) -> 6.75 | F6: 6.5 | G6: 8 | H6: 4.5 | I6: 7
A7: Execution | B7: Are we executing tasks, responsibilities individually and as a team? | C7: 7 | D7: 7 | E7: =AVERAGE(7,8) -> 7.5 | F7: 4 | G7: 7.5 | H7: 7 | I7: 8
A8: Follow Up | B8: After assigning or asking for help or task, or changes are we following up to make sure it is done, complete not just once but over and over to ensure its correct? | C8: 2 | D8: 4 | E8: =AVERAGE(5,8,7) -> 6.6666667 | F8: 7.5 | G8: 7 | H8: 7.5 | I8: 7
A9: TOTAL RATING | C9: =AVERAGE(C3:C8) -> 3.5 | D9: =AVERAGE(D3:D8) -> 6.1666667 | E9: =AVERAGE(E3:E8) -> 6.4027778 | F9: =AVERAGE(F3:F8) -> 6.75 | G9: =AVERAGE(G3:G8) -> 7.1666667 | H9: =AVERAGE(H3:H8) -> 6.75 | I9: =AVERAGE(I3:I8) -> 7.25
